Workbook

Sheet Threat Map
A1: Church Machine (CTMM) vs W7 / Scheme 48 — adversarial test plan for W7 open threats
A2: Source of threats: J. Rees, 'A Security Kernel Based on the Lambda-Calculus', MIT AI Memo 1564 (1996). CTMM mechanisms from ratified design notes; rows marked 'Unknown' or 'Inferred' are Claude's inference, not ratified design.
A3: Legend: yellow cells are for you to fill in after running each test (W7 baseline result, CTMM result, notes). The Pass column computes itself.
A5: # | B5: W7 open threat | C5: Memo § | D5: Closure category | E5: CTMM mechanism | F5: Mechanism status | G5: Test oracle (what must happen) | H5: Coverage method | I5: Evidence class | J5: W7 baseline result | K5: CTMM result | L5: Pass? | M5: Notes / next action
A6: 1 | B6: Revocation impossible | C6: 4.3.5 | D6: Closable now | E6: GT slot version numbers — O(1) revocation | F6: Ratified | G6: Make N copies of a GT; revoke once. Every copy faults; revoke cost independent of N (FPGA cycle counter). | H6: Sweep N = 1…max c-list size; cycle count must be flat | I6: Proven (by test + invariant) | L6: =IF(OR(J6="",K6=""),"Not run",IF(AND(J6="Attack succeeds",K6="Faults as predicted"),"PASS","FAIL")) | M6: Recommended first test spec.
A7: 2 | B7: Untrusted machine code: forged references | C7: 4.3.3 | D7: Closable now | E7: Hardware-checked GT on every reference | F7: Ratified | G7: Forged bit patterns, data-as-capability, out-of-bounds offsets all fault. | H7: Exhaustive over typ / tag / version fields; structured fuzz over offsets | I7: Proven (exhaustive) | L7: =IF(OR(J7="",K7=""),"Not run",IF(AND(J7="Attack succeeds",K7="Faults as predicted"),"PASS","FAIL")) | M7: Strongest claim vs W7.
A8: 3 | B8: Reflection: debugger breaks all boundaries | C8: 4.3.4 | D8: Closable now | E8: Dev/prod split — two root lumps differing by one c-list entry | F8: Ratified | G8: Reachability closure from prod root contains no debug authority. | H8: Graph closure over all c-lists reachable from prod root | I8: Proven (proof by closure) | L8: =IF(OR(J8="",K8=""),"Not run",IF(AND(J8="Attack succeeds",K8="Faults as predicted"),"PASS","FAIL")) | M8: Stronger than a test.
A9: 4 | B9: Ambient authority: ports, load, interaction-environment, dynamic-wind | C9: 3.4 | D9: Closable now | E9: Womb-and-cord birth; Enter-only outsider permission | F9: Ratified | G9: Newborn lump's reachable authority equals exactly what the womb granted. | H9: Authority census at birth for every lump type | I9: Proven (by test + invariant) | L9: =IF(OR(J9="",K9=""),"Not run",IF(AND(J9="Attack succeeds",K9="Faults as predicted"),"PASS","FAIL"))
A10: 5 | B10: Authentication / sealing not supported | C10: 2.3.3, 4.1 | D10: Closable after spec fix | E10: Seals; Abstract GTs (typ=11), non-portable by construction | F10: Ratified (spec conflict) | G10: Unseal without unsealer faults; exporting an Abstract GT across namespaces faults. | H10: Exhaustive over namespace pairs | I10: Modelled until typ conflict resolved | L10: =IF(OR(J10="",K10=""),"Not run",IF(AND(J10="Attack succeeds",K10="Faults as predicted"),"PASS","FAIL")) | M10: Resolve the §0 vs §6 typ contradiction first.
A11: 6 | B11: Quotas: one program exhausts memory | C11: 4.3.5 | D11: Closable with bounds | E11: Per-namespace tracing GC; eviction as pressure relief | F11: Ratified | G11: Hostile namespace allocates unboundedly; neighbours see no failure and latency within stated bound. | H11: Stress test across namespace counts | I11: Modelled (needs numeric bound) | L11: =IF(OR(J11="",K11=""),"Not run",IF(AND(J11="Attack succeeds",K11="Faults as predicted"),"PASS","FAIL")) | M11: Define the latency bound.
A12: 7 | B12: Persistence outside protection | C12: 4.3.5 | D12: Closable with bounds | E12: LUMP lifecycle | F12: Ratified | G12: Evict, reload, compare authority: identical; no file-system path involved. | H12: Round-trip every lump type | I12: Modelled | L12: =IF(OR(J12="",K12=""),"Not run",IF(AND(J12="Attack succeeds",K12="Faults as predicted"),"PASS","FAIL"))
A13: 8 | B13: Preemption / termination; engine response depends on nesting depth | C13: 4.3.1 | D13: Open in CTMM | E13: Not on file | F13: Unknown | G13: Callee loops or nests deeply; caller regains control in bounded time independent of depth. | H13: Sweep nesting depth; response time must be flat | I13: Speculative | L13: =IF(OR(J13="",K13=""),"Not run",IF(AND(J13="Attack succeeds",K13="Faults as predicted"),"PASS","FAIL")) | M13: Hardest gap; critics probe first. Define mechanism.
A14: 9 | B14: Continuations invoked multiple times | C14: 4.3.2 | D14: Open in CTMM | E14: Not on file | F14: Unknown | G14: Callee retains its return path and invokes it twice; second call faults. | H14: All return paths | I14: Speculative | L14: =IF(OR(J14="",K14=""),"Not run",IF(AND(J14="Attack succeeds",K14="Faults as predicted"),"PASS","FAIL")) | M14: Is return one-shot in the CTMM?
A15: 10 | B15: Concurrency: shared cells | C15: Footnote 3 | D15: Open in CTMM | E15: Not on file | F15: Unknown | G15: Racing writers to a shared lump: serialized or faulted. | H15: Randomised interleavings | I15: Speculative | L15: =IF(OR(J15="",K15=""),"Not run",IF(AND(J15="Attack succeeds",K15="Faults as predicted"),"PASS","FAIL"))
A16: 11 | B16: Accountability: who acts for whom | C16: 4.3.5 | D16: Partial | E16: Identity / seal architecture; pioneering window | F16: Ratified (partial) | G16: Every invocation attributable to originating womb. | H16: Trace every call chain in test suite | I16: Modelled | L16: =IF(OR(J16="",K16=""),"Not run",IF(AND(J16="Attack succeeds",K16="Faults as predicted"),"PASS","FAIL")) | M16: Needs precise definition of 'accountable'.
A17: 12 | B17: Schroeder problem: callee remembers/leaks inputs | C17: 4.2.1 | D17: Not closable by test | E17: Enter-only; no outward write authority at entry | F17: Inferred | G17: Reachability: callee holds no outward write authority at entry. | H17: Closure over callee c-list | I17: Proven for explicit channels; covert channels open | L17: =IF(OR(J17="",K17=""),"Not run",IF(AND(J17="Attack succeeds",K17="Faults as predicted"),"PASS","FAIL")) | M17: State plainly that timing/covert channels remain.
A18: 13 | B18: Undecidability of 'might divulge input' | C18: 2.2.6 | D18: Not closable by test | E18: — | F18: n/a | G18: — | H18: — | I18: Mathematical limit | L18: =IF(OR(J18="",K18=""),"Not run",IF(AND(J18="Attack succeeds",K18="Faults as predicted"),"PASS","FAIL")) | M18: CTMM moves the line, does not remove it.
A19: 14 | B19: Trust in administrator / manufacturing chain | C19: 2.2.5 | D19: Not closable by test | E19: Artix-7 silicon + bitstream toolchain | F19: n/a | G19: — | H19: Reproducible bitstreams narrow, do not close | I19: Out of test scope | L19: =IF(OR(J19="",K19=""),"Not run",IF(AND(J19="Attack succeeds",K19="Faults as predicted"),"PASS","FAIL"))
A20: 15 | B20: Distribution / remote invocation | C20: 4.3.5 | D20: Out of scope | E20: — | F20: n/a | G20: — | H20: — | I20: Out of scope | L20: =IF(OR(J20="",K20=""),"Not run",IF(AND(J20="Attack succeeds",K20="Faults as predicted"),"PASS","FAIL")) | M20: Declare explicitly rather than leave implied.

Sheet Summary
A1: Summary by closure category
A3: Closure category | B3: Threats | C3: Passed | D3: Not run
A4: Closable now | B4: =COUNTIF('Threat Map'!$D$6:$D$20,A4) | C4: =COUNTIFS('Threat Map'!$D$6:$D$20,A4,'Threat Map'!$L$6:$L$20,"PASS") | D4: =COUNTIFS('Threat Map'!$D$6:$D$20,A4,'Threat Map'!$L$6:$L$20,"Not run")
A5: Closable after spec fix | B5: =COUNTIF('Threat Map'!$D$6:$D$20,A5) | C5: =COUNTIFS('Threat Map'!$D$6:$D$20,A5,'Threat Map'!$L$6:$L$20,"PASS") | D5: =COUNTIFS('Threat Map'!$D$6:$D$20,A5,'Threat Map'!$L$6:$L$20,"Not run")
A6: Closable with bounds | B6: =COUNTIF('Threat Map'!$D$6:$D$20,A6) | C6: =COUNTIFS('Threat Map'!$D$6:$D$20,A6,'Threat Map'!$L$6:$L$20,"PASS") | D6: =COUNTIFS('Threat Map'!$D$6:$D$20,A6,'Threat Map'!$L$6:$L$20,"Not run")
A7: Partial | B7: =COUNTIF('Threat Map'!$D$6:$D$20,A7) | C7: =COUNTIFS('Threat Map'!$D$6:$D$20,A7,'Threat Map'!$L$6:$L$20,"PASS") | D7: =COUNTIFS('Threat Map'!$D$6:$D$20,A7,'Threat Map'!$L$6:$L$20,"Not run")
A8: Open in CTMM | B8: =COUNTIF('Threat Map'!$D$6:$D$20,A8) | C8: =COUNTIFS('Threat Map'!$D$6:$D$20,A8,'Threat Map'!$L$6:$L$20,"PASS") | D8: =COUNTIFS('Threat Map'!$D$6:$D$20,A8,'Threat Map'!$L$6:$L$20,"Not run")
A9: Not closable by test | B9: =COUNTIF('Threat Map'!$D$6:$D$20,A9) | C9: =COUNTIFS('Threat Map'!$D$6:$D$20,A9,'Threat Map'!$L$6:$L$20,"PASS") | D9: =COUNTIFS('Threat Map'!$D$6:$D$20,A9,'Threat Map'!$L$6:$L$20,"Not run")
A10: Out of scope | B10: =COUNTIF('Threat Map'!$D$6:$D$20,A10) | C10: =COUNTIFS('Threat Map'!$D$6:$D$20,A10,'Threat Map'!$L$6:$L$20,"PASS") | D10: =COUNTIFS('Threat Map'!$D$6:$D$20,A10,'Threat Map'!$L$6:$L$20,"Not run")
A11: Total | B11: =SUM(B4:B10) | C11: =SUM(C4:C10) | D11: =SUM(D4:D10)

Sheet Method
A1: Test method
A3: What closes a threat | B3: A test only shows one attack failed. A threat is closed by: (1) a named CTMM mechanism, (2) an invariant true by construction, (3) an adversarial test plus a coverage argument. Small typ/tag fields make exhaustive coverage feasible.
A4: Step 1 — Baseline | B4: Write the attack as a W7 / Scheme 48 program and show it succeeds.
A5: Step 2 — Port | B5: Translate the same attack into a CTMM lump, using the telecom running example (dot.phone.Dial).
A6: Step 3 — Oracle | B6: State the expected fault: which fault, at which instruction, within what cycle bound (FPGA cycle counter).
A7: Step 4 — Coverage | B7: Run exhaustively or by structured fuzzing over the relevant field: GT typ, version, offset, or c-list slot.
A8: Pass criterion | B8: W7 baseline attack succeeds AND the CTMM version faults at the predicted point.
A9: Evidence classes | B9: Proven = invariant + exhaustive test or closure proof. Modelled = mechanism specified, bound or spec still to fix. Speculative = no mechanism on file.
A10: Source | B10: Rees, J. 'A Security Kernel Based on the Lambda-Calculus', MIT AI Memo 1564, 1996. https://dspace.mit.edu/handle/1721.1/5944

Sheet Completeness
A1: ID | B1: Area | C1: Requirement / issue | D1: Scope | E1: Priority | F1: Status | G1: Owner | H1: Dependencies | I1: Current evidence / gap | J1: Closure criterion / next action | K1: Source reference | L1: Reviewed date | M1: Evidence / result link | N1: Due date
A2: W7-01 | B2: W7 security | C2: Revocation impossible | D2: Phase 1 assurance | E2: High | F2: Not run | G2: Unassigned | I2: Original workbook claim, not independently qualified. See original row. | J2: Make N copies of a GT; revoke once. Every copy faults; revoke cost independent of N (FPGA cycle counter). Coverage: Sweep N = 1…max c-list size; cycle count must be flat | K2: Workbook: Threat Map row 6; docs/phase-1/W7-plus-plus-test-objectives.md | L2: 2026-10-17
A3: W7-02 | B3: W7 security | C3: Untrusted machine code: forged references | D3: Phase 1 assurance | E3: High | F3: Not run | G3: Unassigned | I3: Original workbook claim, not independently qualified. See original row. | J3: Forged bit patterns, data-as-capability, out-of-bounds offsets all fault. Coverage: Exhaustive over typ / tag / version fields; structured fuzz over offsets | K3: Workbook: Threat Map row 7; docs/phase-1/W7-plus-plus-test-objectives.md | L3: 2026-10-17
A4: W7-03 | B4: W7 security | C4: Reflection: debugger breaks all boundaries | D4: Phase 1 assurance | E4: High | F4: Not run | G4: Unassigned | I4: Original workbook claim, not independently qualified. See original row. | J4: Reachability closure from prod root contains no debug authority. Coverage: Graph closure over all c-lists reachable from prod root | K4: Workbook: Threat Map row 8; docs/phase-1/W7-plus-plus-test-objectives.md | L4: 2026-10-17
A5: W7-04 | B5: W7 security | C5: Ambient authority: ports, load, interaction-environment, dynamic-wind | D5: Phase 1 assurance | E5: High | F5: Not run | G5: Unassigned | I5: Original workbook claim, not independently qualified. See original row. | J5: Newborn lump's reachable authority equals exactly what the womb granted. Coverage: Authority census at birth for every lump type | K5: Workbook: Threat Map row 9; docs/phase-1/W7-plus-plus-test-objectives.md | L5: 2026-10-17
A6: W7-05 | B6: W7 security | C6: Authentication / sealing not supported | D6: Phase 1 assurance | E6: High | F6: Not run | G6: Unassigned | I6: Original workbook claim, not independently qualified. See original row. | J6: Unseal without unsealer faults; exporting an Abstract GT across namespaces faults. Coverage: Exhaustive over namespace pairs | K6: Workbook: Threat Map row 10; docs/phase-1/W7-plus-plus-test-objectives.md | L6: 2026-10-17
A7: W7-06 | B7: W7 security | C7: Quotas: one program exhausts memory | D7: Phase 1 assurance | E7: High | F7: Not run | G7: Unassigned | I7: Original workbook claim, not independently qualified. See original row. | J7: Hostile namespace allocates unboundedly; neighbours see no failure and latency within stated bound. Coverage: Stress test across namespace counts | K7: Workbook: Threat Map row 11; docs/phase-1/W7-plus-plus-test-objectives.md | L7: 2026-10-17
A8: W7-07 | B8: W7 security | C8: Persistence outside protection | D8: Phase 1 assurance | E8: High | F8: Not run | G8: Unassigned | I8: Original workbook claim, not independently qualified. See original row. | J8: Evict, reload, compare authority: identical; no file-system path involved. Coverage: Round-trip every lump type | K8: Workbook: Threat Map row 12; docs/phase-1/W7-plus-plus-test-objectives.md | L8: 2026-10-17
A9: W7-08 | B9: W7 security | C9: Preemption / termination; engine response depends on nesting depth | D9: Phase 1 assurance | E9: High | F9: Not run | G9: Unassigned | I9: Original workbook claim, not independently qualified. See original row. | J9: Callee loops or nests deeply; caller regains control in bounded time independent of depth. Coverage: Sweep nesting depth; response time must be flat | K9: Workbook: Threat Map row 13; docs/phase-1/W7-plus-plus-test-objectives.md | L9: 2026-10-17
A10: W7-09 | B10: W7 security | C10: Continuations invoked multiple times | D10: Phase 1 assurance | E10: High | F10: Not run | G10: Unassigned | I10: Original workbook claim, not independently qualified. See original row. | J10: Callee retains its return path and invokes it twice; second call faults. Coverage: All return paths | K10: Workbook: Threat Map row 14; docs/phase-1/W7-plus-plus-test-objectives.md | L10: 2026-10-17
A11: W7-10 | B11: W7 security | C11: Concurrency: shared cells | D11: Phase 1 assurance | E11: High | F11: Not run | G11: Unassigned | I11: Original workbook claim, not independently qualified. See original row. | J11: Racing writers to a shared lump: serialized or faulted. Coverage: Randomised interleavings | K11: Workbook: Threat Map row 15; docs/phase-1/W7-plus-plus-test-objectives.md | L11: 2026-10-17
A12: W7-11 | B12: W7 security | C12: Accountability: who acts for whom | D12: Phase 1 assurance | E12: High | F12: Not run | G12: Unassigned | I12: Original workbook claim, not independently qualified. See original row. | J12: Every invocation attributable to originating womb. Coverage: Trace every call chain in test suite | K12: Workbook: Threat Map row 16; docs/phase-1/W7-plus-plus-test-objectives.md | L12: 2026-10-17
A13: W7-12 | B13: W7 security | C13: Schroeder problem: callee remembers/leaks inputs | D13: Phase 1 assurance | E13: High | F13: Not run | G13: Unassigned | I13: Original workbook claim, not independently qualified. See original row. | J13: Reachability: callee holds no outward write authority at entry. Coverage: Closure over callee c-list | K13: Workbook: Threat Map row 17; docs/phase-1/W7-plus-plus-test-objectives.md | L13: 2026-10-17
... A16: W7-15 | B16: W7 security | C16: Distribution / remote invocation | D16: Phase 2 | E16: High | F16: Out of scope | G16: Unassigned | I16: Original workbook claim, not independently qualified. See original row. | J16: — Coverage: — | K16: Workbook: Threat Map row 20; docs/phase-1/W7-plus-plus-test-objectives.md | L16: 2026-10-17
A17: H01 | B17: Hardware acceptance | C17: Every ordinary opcode, all register positions, DR0 and aliased inputs; ALU 0, ±1, signed extrema, carry/borrow; shifts 0/1/31. | D17: Phase 1 hardware | E17: High | F17: Not run | G17: Unassigned | H17: See source gate dependencies | I17: Defined objective; full acceptance not established by this tracker. | J17: Exact result, NZCV and preserved state against the core reference; close its oracle gaps before declaring full coverage. | K17: docs/phase-1/04-release/isa-to-fpga-alignment-plan.md | L17: 2026-10-17
A18: H02 | B18: Hardware acceptance | C18: All 16 NZCV combinations × every defined condition; false-condition invalid operands, CR13, NULL/EXACT and malformed encodings. | D18: Phase 1 hardware | E18: High | F18: Not run | G18: Unassigned | H18: See source gate dependencies | I18: Defined objective; full acceptance not established by this tracker. | J18: Skip has no operand effect/fault; only next fetch and independent watchdog behavior remain. Reserved NV is not silently assumed. | K18: docs/phase-1/04-release/isa-to-fpga-alignment-plan.md | L18: 2026-10-17
A19: H03 | B19: Hardware acceptance | C19: Each approved CALL form; both signs; row magnitudes 0/31, method 0/127 or 0/2047; LOAD/SAVE/DREAD/DWRITE ±1023, BRANCH ±262143. | D19: Phase 1 hardware | E19: High | F19: Not run | G19: Unassigned | H19: See source gate dependencies | I19: Defined objective; full acceptance not established by this tracker. | J19: Hand-checked packed word and latched operands; correct byte/word conversion; no wrap/truncation. Zero, last-valid and first-invalid effective indices. | K19: docs/phase-1/04-release/isa-to-fpga-alignment-plan.md | L19: 2026-10-17
A20: H04 | B20: Hardware acceptance | C20: BFEXT/BFINS width 1/31 and invalid 0; positions 0/31, crossing bit 31, DR underflow/overflow, shared source/destination. | D20: Phase 1 hardware | E20: High | F20: Not run | G20: Unassigned | H20: See source gate dependencies | I20: Defined objective; full acceptance not established by this tracker. | J20: Exact result and flags or fault before destination mutation; preserve unaffected insertion bits. | K20: docs/phase-1/04-release/isa-to-fpga-alignment-plan.md | L20: 2026-10-17
A21: H05 | B21: Hardware acceptance | C21: Direct/indexed CALL methods 0, first/last public, private zero and outside table/code; nested calls, RETURN mask 0/all/each bit, root/empty/corrupt continuation; LAMBDA. | D21: Phase 1 hardware | E21: High | F21: Not run | G21: Unassigned | H21: See source gate dependencies | I21: Defined objective; full acceptance not established by this tracker. | J21: Correct E authority, c-list/code reconstruction, continuation and mask; no hidden snapshot or unchecked fast return. | K21: docs/phase-1/04-release/isa-to-fpga-alignment-plan.md | L21: 2026-10-17 | M21: BASE-05: docs/reviews/phase1-baseline/README.md
A22: H06 | B22: Hardware acceptance | C22: GT classes, permissions, domains, bounds, stale generation; mutate each integrity-covered bit and F/G separately; denied/allowed MMIO. | D22: Phase 1 hardware | E22: High | F22: Not run | G22: Unassigned | H22: See source gate dependencies | I22: Defined objective; full acceptance not established by this tracker. | J22: Required access fails before unauthorized effects; full 9-bit equality, unchanged versions and exact integrity formula. No inferred permission from slot membership. | K22: docs/phase-1/04-release/isa-to-fpga-alignment-plan.md | L22: 2026-10-17
A23: H07 | B23: Hardware acceptance | C23: NULL literal/nonzero/B variants; EXACT equal/unequal non-NULL, one/both NULL; raw NULL modifier 31; condition skips. | D23: Phase 1 hardware | E23: High | F23: Not run | G23: Unassigned | H23: See source gate dependencies | I23: Defined objective; full acceptance not established by this tracker. | J23: Exact approved NZCV or pre-mutation fault at the TPERM instruction. Equality never proves validity. | K23: docs/phase-1/04-release/isa-to-fpga-alignment-plan.md | L23: 2026-10-17
A24: H08 | B24: Hardware acceptance | C24: Valid, malformed and suspended/root Thread contexts; permission-bearing operand GT; unused invalid c-list row then use it. | D24: Phase 1 hardware | E24: High | F24: Not run | G24: Unassigned | H24: See source gate dependencies | I24: Defined objective; full acceptance not established by this tracker. | J24: Context failures 0x1D, separate operand permission failure 0x1E; no eager entire-c-list scan; each restored CR GT passes mLoad. | K24: docs/phase-1/04-release/isa-to-fpga-alignment-plan.md | L24: 2026-10-17
A25: H09 | B25: Hardware acceptance | C25: CHANGE self/helper/other; SWITCH both legal spellings, both signs, CR15.M absent; invalid Namespace/entry; CR13 operands. | D25: Phase 1 hardware | E25: High | F25: Not run | G25: Unassigned | H25: See source gate dependencies | I25: Defined objective; full acceptance not established by this tracker. | J25: Save/load order, unchanged ordinary CR15, shared SWITCH authority, fixed slot-2 entry, no CR13 writes; no target execution on failure. | K25: docs/phase-1/04-release/isa-to-fpga-alignment-plan.md | L25: 2026-10-17 | M25: BASE-05: docs/reviews/phase1-baseline/README.md
A26: H10 | B26: Hardware acceptance | C26: Cold configuration, warm reset, authorized marker, same word at wrong PC/from RAM, replay after acceptance/fault, malformed final CALL CR0. | D26: Phase 1 hardware | E26: High | F26: Not run | G26: Unassigned | H26: See source gate dependencies | I26: Defined objective; full acceptance not established by this tracker. | J26: One-shot 0x27000001 only at immutable ROM site; no extra CR12.M; ROM fetch authority ends only on successful final CALL. | K26: docs/phase-1/04-release/isa-to-fpga-alignment-plan.md | L26: 2026-10-17 | M26: BASE-04: docs/reviews/phase1-baseline/README.md
A27: H11 | B27: Hardware acceptance | C27: Boot pair match, slot-1 mismatch, slot-2 mismatch after CR15 load, pair equal to itself but not bitstream; ordinary versus guarded handoff. | D27: Phase 1 hardware | E27: High | F27: Not run | G27: Unassigned | H27: See source gate dependencies | I27: Defined objective; full acceptance not established by this tracker. | J27: VERSION with correct slot; no target activation, retry or rollback; ordinary entry version 0 versus guarded expected version. | K27: docs/phase-1/04-release/isa-to-fpga-alignment-plan.md | L27: 2026-10-17 | M27: BASE-04: docs/reviews/phase1-baseline/README.md
A28: H12 | B28: Hardware acceptance | C28: Default and configured Namespace capacity, first/last/outside slot and word, all fixed service slots, maximum intended allocation. | D28: Phase 1 hardware | E28: High | F28: Not run | G28: Unassigned | H28: See source gate dependencies | I28: Defined objective; full acceptance not established by this tracker. | J28: Ascending four-word entries; 256-slot default/limit 1023; slots 0/1/2/8/9/14/15; whole Phase 1 footprint fits half actual FPGA memory. | K28: docs/phase-1/04-release/isa-to-fpga-alignment-plan.md | L28: 2026-10-17 | M28: BASE-04: docs/reviews/phase1-baseline/README.md
A29: H13 | B29: Hardware acceptance | C29: All eight valid watchdog controls; power-on then warm reset with exemption on/off; each selector change while running. | D29: Phase 1 hardware | E29: High | F29: Not run | G29: Unassigned | H29: See source gate dependencies | I29: Defined objective; full acceptance not established by this tracker. | J29: Initial 0x5; controls retained across reset, elapsed count not retained; selector alone never extends current interval; readback is programmed selection. | K29: docs/phase-1/04-release/isa-to-fpga-alignment-plan.md | L29: 2026-10-17
A30: H14 | B30: Hardware acceptance | C30: Every duration; instruction retirement, CALL/RETURN loops, stalls, self/helper CHANGE and SWITCH; completion before/at/after deadline. | D30: Phase 1 hardware | E30: High | F30: Not run | G30: Unassigned | H30: See source gate dependencies | I30: Defined objective; full acceptance not established by this tracker. | J30: Ungated elapsed time; only successful pre-deadline transfer renews; expiry wins equality, code 0x1F; no CR13/IRQ action. | K30: docs/phase-1/04-release/isa-to-fpga-alignment-plan.md | L30: 2026-10-17
A31: H15 | B31: Hardware acceptance | C31: Exemption enter/exit, combined selector+exit (including 0x6), repeated non-exempt writes; every reserved control bit. | D31: Phase 1 hardware | E31: High | F31: Not run | G31: Unassigned | H31: See source gate dependencies | I31: Defined objective; full acceptance not established by this tracker. | J31: Fresh same-write duration on exit; repeated 0 does not renew; reserved bits read zero, writes wholly reject with 0x0B without stopping time. | K31: docs/phase-1/04-release/isa-to-fpga-alignment-plan.md | L31: 2026-10-17
A32: H16 | B32: Hardware acceptance | C32: Exemption/selector update at expiry; instruction fault at expiry; incoming mLoad failure at renewal. | D32: Phase 1 hardware | E32: High | F32: Not run | G32: Unassigned | H32: See source gate dependencies | I32: Defined objective; full acceptance not established by this tracker. | J32: Whole control rejection at expiry; instruction fault wins reporting but not containment; failed transfer never renews. | K32: docs/phase-1/04-release/isa-to-fpga-alignment-plan.md | L32: 2026-10-17
A33: H17 | B33: Hardware acceptance | C33: Expiry before/on/after program-write acceptance, delayed completion, partial multiwrite instruction and failed outgoing save. | D33: Phase 1 hardware | E33: High | F33: Not run | G33: Unassigned | H33: See source gate dependencies | I33: Defined objective; full acceptance not established by this tracker. | J33: Stop admission immediately; at most one accepted write completes within measured bound; no remaining instruction writes, retry, rollback or recovery write before completion. Failed validated save is not reported successful. | K33: docs/phase-1/04-release/isa-to-fpga-alignment-plan.md | L33: 2026-10-17
A34: H18 | B34: Hardware acceptance | C34: HARDFAULT 0xF7000000, retired opcodes, wrong-context reset marker, bad fetch/entry; recovery that changes visible PC. | D34: Phase 1 hardware | E34: High | F34: Not run | G34: Unassigned | H34: See source gate dependencies | I34: Defined objective; full acceptance not established by this tracker. | J34: First fault code/location and pre-recovery state captured; no HALT substitution, speculative retirement or proof/private-state leakage. | K34: docs/phase-1/04-release/isa-to-fpga-alignment-plan.md | L34: 2026-10-17 | M34: BASE-05: docs/reviews/phase1-baseline/README.md
A35: H19 | B35: Hardware acceptance | C35: Behavioral, emitted RTL, mapped model and board replay of the same fixture. | D35: Phase 1 hardware | E35: High | F35: Not run | G35: Unassigned | H35: See source gate dependencies | I35: Defined objective; full acceptance not established by this tracker. | J35: Compare committed registers/flags/memory/faults, not internal cycle counts except deadline/completion bounds. No forced X values or stale model accepted. | K35: docs/phase-1/04-release/isa-to-fpga-alignment-plan.md | L35: 2026-10-17 | M35: BASE-06: docs/reviews/phase1-baseline/README.md
A36: H20 | B36: Hardware acceptance | C36: Exact build cold/warm reboot, repeated handoffs and fault/recovery trials; memory/ROM initialization and retained controls. | D36: Phase 1 hardware | E36: High | F36: Not run | G36: Unassigned | H36: See source gate dependencies | I36: Defined objective; full acceptance not established by this tracker. | J36: Repeatable outcomes tied to bundle/input hashes, board identity, clock, logs and observed completion; no prior-run telemetry counted as new evidence. | K36: docs/phase-1/04-release/isa-to-fpga-alignment-plan.md | L36: 2026-10-17 | M36: BASE-06: docs/reviews/phase1-baseline/README.md
A37: S01 | B37: Software acceptance | C37: One IDE/several CMs; network T/local GT binding and virtual objects. Direct CM-to-CM, multiple IDEs and the two-Namespaces-on-one-FPGA networking test remain Phase 2. | D37: Phase 1 software | E37: High | F37: Not run | G37: Unassigned | H37: See source gate dependencies | I37: Defined objective; full acceptance not established by this tracker. | K37: docs/phase-1/04-release/isa-to-fpga-alignment-plan.md | L37: 2026-10-17
A38: S02 | B38: Software acceptance | C38: Explicit loading; working Mint, pkverify and controlled nstab. Create/Replace/Destroy for application Abstractions, Threads, LS c-lists and RW data; no Mint MMIO/Namespace creation; growth estimates are not measured allocations. | D38: Phase 1 software | E38: High | F38: Not run | G38: Unassigned | H38: See source gate dependencies | I38: Defined objective; full acceptance not established by this tracker. | K38: docs/phase-1/04-release/isa-to-fpga-alignment-plan.md | L38: 2026-10-17
A39: S03 | B39: Software acceptance | C39: Per-operation/target PassKey GT plus separate 128-bit proof; validate before EXACT; Genesis-only setup, sharing and revokers; reusable-until-revoked; pair-only revocation. Negative cases include missing proof, NULL/equal invalid GTs, stale/revoked and insufficient authority. SAVE identifies the GT-side detection point, not a completed proof mechanism. | D39: Phase 1 software | E39: High | F39: Not run | G39: Unassigned | H39: See source gate dependencies | I39: Defined objective; full acceptance not established by this tracker. | K39: docs/phase-1/04-release/isa-to-fpga-alignment-plan.md | L39: 2026-10-17
A40: S04 | B40: Software acceptance | C40: Single-scope LAMBDA alone references NSRW-GT; one exclusive non-yielding slot update; verify/prepare before writes, publish only after confirmed writes. Reject resident/active Thread/code/c-list replacement or destruction before mutation. | D40: Phase 1 software | E40: High | F40: Not run | G40: Unassigned | H40: See source gate dependencies | I40: Defined objective; full acceptance not established by this tracker. | K40: docs/phase-1/04-release/isa-to-fpga-alignment-plan.md | L40: 2026-10-17
A41: S05 | B41: Software acceptance | C41: First issue 0; release advances without wrap; reuse retained version; 510→511 permanently retires; stale issued GTs fault; full block zeroed before reuse; size-class pool tracking. Software enforces allocation policy; hardware never increments. | D41: Phase 1 software | E41: High | F41: Not run | G41: Unassigned | H41: See source gate dependencies | I41: Defined objective; full acceptance not established by this tracker. | K41: docs/phase-1/04-release/isa-to-fpga-alignment-plan.md | L41: 2026-10-17
A42: S06 | B42: Software acceptance | C42: Retained boot-pair values 0…510 per half; unchanged builds retain them; explicitly changed configuration provisions matching bitstream/GTs. CR0-only policy defaults retain, saved per configuration; alternate new-guard choice does not bypass validation. | D42: Phase 1 software | E42: High | F42: Not run | G42: Unassigned | H42: See source gate dependencies | I42: Defined objective; full acceptance not established by this tracker. | K42: docs/phase-1/04-release/isa-to-fpga-alignment-plan.md | L42: 2026-10-17
...

Sheet Progress
A1: Phase 1 completeness — evidence-based tracking | B1: Count / rate
A2: Updated | B2: 2026-10-17
A3: Total tracked rows | B3: =COUNTA(Completeness!A2:A10000) -> 113
A4: Open | B4: =COUNTIF(Completeness!F2:F10000,"Open") -> 24
A5: Blocked | B5: =COUNTIF(Completeness!F2:F10000,"Blocked") -> 6
A6: Not run | B6: =COUNTIF(Completeness!F2:F10000,"Not run") -> 56
A7: Needs verification | B7: =COUNTIF(Completeness!F2:F10000,"Needs verification") -> 24
A8: In progress | B8: =COUNTIF(Completeness!F2:F10000,"In progress") -> 0
A9: Complete | B9: =COUNTIF(Completeness!F2:F10000,"Complete") -> 2
A10: Failed | B10: =COUNTIF(Completeness!F2:F10000,"Failed") -> 0
A11: Out of scope | B11: =COUNTIF(Completeness!F2:F10000,"Out of scope") -> 1
A12: In-scope completion | B12: =IFERROR(COUNTIF(Completeness!F2:F10000,"Complete")/(COUNTA(Completeness!A2:A10000)-COUNTIF(Completeness!F2:F10000,"Out of scope")),0) -> 0.017857143
A13: Interpretation | B13: Counts of different items; each item has one status. Row completion is not ISA/security coverage.
A14: Area | B14: Tracked | C14: Complete items | D14: Blocked items
A15: CM objectives | B15: =COUNTIF(Completeness!B2:B10000,A15) -> 8 | C15: =COUNTIFS(Completeness!B2:B10000,A15,Completeness!F2:F10000,"Complete") -> 0 | D15: =COUNTIFS(Completeness!B2:B10000,A15,Completeness!F2:F10000,"Blocked") -> 0
A16: Hardware acceptance | B16: =COUNTIF(Completeness!B2:B10000,A16) -> 20 | C16: =COUNTIFS(Completeness!B2:B10000,A16,Completeness!F2:F10000,"Complete") -> 0 | D16: =COUNTIFS(Completeness!B2:B10000,A16,Completeness!F2:F10000,"Blocked") -> 0
A17: IDE | B17: =COUNTIF(Completeness!B2:B10000,A17) -> 6 | C17: =COUNTIFS(Completeness!B2:B10000,A17,Completeness!F2:F10000,"Complete") -> 1 | D17: =COUNTIFS(Completeness!B2:B10000,A17,Completeness!F2:F10000,"Blocked") -> 0
A18: Mint gates | B18: =COUNTIF(Completeness!B2:B10000,A18) -> 8 | C18: =COUNTIFS(Completeness!B2:B10000,A18,Completeness!F2:F10000,"Complete") -> 0 | D18: =COUNTIFS(Completeness!B2:B10000,A18,Completeness!F2:F10000,"Blocked") -> 0
A19: Missing functions | B19: =COUNTIF(Completeness!B2:B10000,A19) -> 7 | C19: =COUNTIFS(Completeness!B2:B10000,A19,Completeness!F2:F10000,"Complete") -> 0 | D19: =COUNTIFS(Completeness!B2:B10000,A19,Completeness!F2:F10000,"Blocked") -> 4
A20: Named abstractions | B20: =COUNTIF(Completeness!B2:B10000,A20) -> 12 | C20: =COUNTIFS(Completeness!B2:B10000,A20,Completeness!F2:F10000,"Complete") -> 0 | D20: =COUNTIFS(Completeness!B2:B10000,A20,Completeness!F2:F10000,"Blocked") -> 0
A21: Performance | B21: =COUNTIF(Completeness!B2:B10000,A21) -> 6 | C21: =COUNTIFS(Completeness!B2:B10000,A21,Completeness!F2:F10000,"Complete") -> 0 | D21: =COUNTIFS(Completeness!B2:B10000,A21,Completeness!F2:F10000,"Blocked") -> 0
A22: RTL / bitstream | B22: =COUNTIF(Completeness!B2:B10000,A22) -> 3 | C22: =COUNTIFS(Completeness!B2:B10000,A22,Completeness!F2:F10000,"Complete") -> 0 | D22: =COUNTIFS(Completeness!B2:B10000,A22,Completeness!F2:F10000,"Blocked") -> 0
A23: Seal storage | B23: =COUNTIF(Completeness!B2:B10000,A23) -> 5 | C23: =COUNTIFS(Completeness!B2:B10000,A23,Completeness!F2:F10000,"Complete") -> 0 | D23: =COUNTIFS(Completeness!B2:B10000,A23,Completeness!F2:F10000,"Blocked") -> 1
A24: Simulator / ISA | B24: =COUNTIF(Completeness!B2:B10000,A24) -> 5 | C24: =COUNTIFS(Completeness!B2:B10000,A24,Completeness!F2:F10000,"Complete") -> 0 | D24: =COUNTIFS(Completeness!B2:B10000,A24,Completeness!F2:F10000,"Blocked") -> 1
A25: Software acceptance | B25: =COUNTIF(Completeness!B2:B10000,A25) -> 7 | C25: =COUNTIFS(Completeness!B2:B10000,A25,Completeness!F2:F10000,"Complete") -> 0 | D25: =COUNTIFS(Completeness!B2:B10000,A25,Completeness!F2:F10000,"Blocked") -> 0
A26: Specification | B26: =COUNTIF(Completeness!B2:B10000,A26) -> 2 | C26: =COUNTIFS(Completeness!B2:B10000,A26,Completeness!F2:F10000,"Complete") -> 1 | D26: =COUNTIFS(Completeness!B2:B10000,A26,Completeness!F2:F10000,"Blocked") -> 0
A27: W7 security | B27: =COUNTIF(Completeness!B2:B10000,A27) -> 15 | C27: =COUNTIFS(Completeness!B2:B10000,A27,Completeness!F2:F10000,"Complete") -> 0 | D27: =COUNTIFS(Completeness!B2:B10000,A27,Completeness!F2:F10000,"Blocked") -> 0
A28: Baseline audit | B28: =COUNTIF(Completeness!B2:B10000,A28) -> 9 | C28: =COUNTIFS(Completeness!B2:B10000,A28,Completeness!F2:F10000,"Complete") -> 0 | D28: =COUNTIFS(Completeness!B2:B10000,A28,Completeness!F2:F10000,"Blocked") -> 0

Sheet Tracking guide
A1: Rule | B1: Meaning
A2: Purpose | B2: Expanded CTMM W7 completeness tracker; original Threat Map, Summary and Method retained without changed cells/formulas/styles.
A3: Original claims | B3: Original Ratified/Proven labels are supplied claims, not newly verified findings. Original Summary covers only the 15 threats; Progress covers the new register.
A4: Complete | B4: Closure criterion satisfied at its stated evidence level; cite dated reproducible evidence. Documentation completion is not hardware acceptance.
A5: Needs verification | B5: Implementation, reported merge or failure exists, but current end-to-end acceptance/root cause has not been verified here.
A6: Open / Blocked | B6: Open: work or decision remains. Blocked: prerequisite authority, contract or mechanism missing. Not run: defined objective with no qualifying run recorded.
A7: No invented status | B7: No new simulator, RTL or hardware runs were performed to populate this workbook; workflow snapshot failures are leads, not confirmed current defects.
A8: Maintaining progress | B8: Edit Completeness, assign Owner and Due date, add evidence, update Reviewed date and dependencies. Append rows within the Excel table; summaries cover rows 2–10000.
A9: Evidence identity | B9: Record exact source, fixture/artifact, build/board, command, date, outcome and exclusions. Never put credentials, keys, proofs or private records in this workbook.
A10: Scope | B10: Phase 1 hardware and software delivery are separate gates. Phase 2 networking remains out of scope. Proposed ECC and running-bit interfaces are not approved by this tracker.
A11: Seal storage | B11: Reconcile authoritative seal semantics/storage with existing implementations; distinguish authenticity seals, public integrity checks, secret proof custody and ECC.
A12: Calculations | B12: Excel/LibreOffice recalculates formulas on open. Python does not evaluate them. Completion percentage is unweighted row closure, not a security-confidence metric.
... A15: Namespace authority | B15: Genesis-approved Namespace selection is authoritative. A manifest may index library/history files, but missing, archived or duplicate catalog rows cannot veto independently verified selected bytes. BASE-02 tracks the competing test requirement, not a request to repair approved selections.

Sheet Baseline audit
A1: ID | B1: Area | C1: Classification / confidence | D1: Observation | E1: Next action | F1: Related requirements
A2: BASE-01 | B2: Assembler/compiler | C2: Confirmed dependency-initialization failure; not an ISA verdict | D2: Existing assembler workflow throws TypeError: ChurchAssembler is not a constructor at compiler line 220. Fresh in-memory probe reproduces it with global assembler undefined; injecting the real constructor removes this exception (the sample still has one compile diagnostic). | E2: Establish explicit Node/compiler dependency setup and regression coverage; rerun isolated assembler suite before interpreting encoding failures. Do not weaken retired-opcode diagnostics. | F2: SIM-01; REL-03
A3: BASE-02 | B3: Namespace authority | C3: Test imposes a competing manifest-authority requirement | D3: Selected SelfTest has one active matching catalog row; selected WukongCallHome and CapabilityTest have zero. All three selected binary hashes match their files. Genesis confirms the approved Namespace list is authoritative; missing active catalog rows do not invalidate these selections. Hash agreement alone is not full execution qualification. Subsequent implementation: admission and R26 catalog veto removed; see docs/reviews/phase1-baseline/namespace-authority-progress.md | E3: Verify remaining save/preview/image consumers against Namespace authority. Preserve exact-byte and allocation checks; no catalog repair or reselection merely for archive flags. | F3: RES-SelfTest; RES-WukongCallHome; RES-CapabilityTest; IDE-03
A4: BASE-03 | B4: LUMP GT validator | C4: Legacy-oracle conflict; affected binary validity not established | D4: Four reported R22 failures use _gt_word0_violation, which declares bit 26 spare and rejects it. The test itself notes Abstract GT encodings use bits 26:25=11. The four reported cases are 04b2913d, 3b057bbb, Ethernet.1.b169bba4 and Ethernet.1.fc72b0e3. | E4: Classify each rejected word by approved type and permissions; replace the obsolete blanket rule only under the current contract. Do not declare all four artifacts valid just because the old rule is wrong. | F4: SIM-01; SEAL-02; REL-03
A5: BASE-04 | B5: Boot-image agreement | C5: Shared generator/fixture contract failure; root cause provisional | D5: All 18 reported failures stop at mandatory NS slot 2 is zeroed; 8 other cases passed. Tests build synthetic Boot.Abstr fixtures in temporary directories; generator still requires legacy slots (0,1,2,3,4,5,6,10). Agreement is not reached in these failed cases. | E5: Trace fixture selection, generation policy and validator mode in an isolated copy. Reconcile approved slot-2 entry versus legacy device/profile semantics; do not remove validation merely to pass tests. | F5: SIM-03; H10; H11; H12
A6: BASE-05 | B6: RTL boot/control | C6: Unresolved fixture/implementation/oracle failures | D6: Existing run: 8 failed, 46 passed. Failures cover SWITCH outcomes, delayed-fault issuer attribution, nested CALL/RETURN and saved-PC validation. No fresh RTL simulation was performed. | E6: Capture instruction words and pre-fault state, verify approved fixture encodings, then replay minimal isolated cases. Keep implementation defects possible until evidence excludes them. | F6: SIM-02; SIM-03; H05; H09; H18
A7: BASE-06 | B7: Generated initialization | C7: Reported generated-artifact/source mismatch; not freshly recomputed | D7: Existing guard: RTLIL init ROM 2693 entries versus Python source 2694; 1 failed, 25 passed in that suite. | E7: Freeze source and approved image first; then regenerate and qualify exact outputs under separate authorization. Do not equate a one-entry count fix with a qualified bitstream. | F7: REL-01; H19; H20
A8: BASE-07 | B8: SelfTest freshness | C8: Reported source/entry-format drift, not observed execution failure | D8: Selected SelfTest hash is intact. Existing freshness guard says instruction body MATCH, embedded text DIFFERENT, method-entry format DIFFERENT. The first failing command prevents the chained guard-test command from running. | E8: Independently inspect actual CALL dispatch/decoder behavior for the exact selected artifact before proposing replacement. Preserve the selected bytes and distinguish source freshness from execution compatibility. | F8: RES-SelfTest; SIM-05
A9: BASE-08 | B9: API reference suite | C9: Probable fixture/contract drift; not a fresh test result | D9: Existing run fails in test_abs_saved_api.js: compiled method declarations unavailable. The fixture invokes _formatLumpApiDefinition('LED', []); failure occurs before the advertised reference comparison completes. | E9: Supply authentic compiled metadata in the fixture, or establish why valid metadata is lost; retain fail-closed refusal to infer API from another LUMP. | F9: IDE-06; REL-03
A10: BASE-09 | B10: Bitstream provenance | C10: Confirmed current-source drift from recorded build | D10: Fresh hash comparison finds 22 of 39 recorded input fingerprints differ from current files. The record's historical “verified” label is not qualification of today's source. | E10: Freeze the candidate source/configuration; obtain matching generation, build/timing, artifact hashes and authorized physical evidence. Do not relabel the historical bitstream. | F10: REL-01; REL-02; CM-H
